
Error: class uri 'gevent' invalid or not found: 

[Traceback (most recent call last):
  File "/usr/lib/python3/dist-packages/gunicorn/workers/ggevent.py", line 14, in <module>
    import gevent
ModuleNotFoundError: No module named 'gevent'

During handling of the above exception, another exception occurred:

Traceback (most recent call last):
  File "/usr/lib/python3/dist-packages/gunicorn/util.py", line 99, in load_class
    mod = importlib.import_module('.'.join(components))
  File "/usr/lib/python3.8/importlib/__init__.py", line 127, in import_module
    return _bootstrap._gcd_import(name[level:], package, level)
  File "<frozen importlib._bootstrap>", line 1014, in _gcd_import
  File "<frozen importlib._bootstrap>", line 991, in _find_and_load
  File "<frozen importlib._bootstrap>", line 975, in _find_and_load_unlocked
  File "<frozen importlib._bootstrap>", line 671, in _load_unlocked
  File "<frozen importlib._bootstrap_external>", line 848, in exec_module
  File "<frozen importlib._bootstrap>", line 219, in _call_with_frames_removed
  File "/usr/lib/python3/dist-packages/gunicorn/workers/ggevent.py", line 16, in <module>
    raise RuntimeError("gevent worker requires gevent 1.4 or higher")
RuntimeError: gevent worker requires gevent 1.4 or higher
]


Error: class uri 'gevent' invalid or not found: 

[Traceback (most recent call last):
  File "/usr/lib/python3/dist-packages/gunicorn/workers/ggevent.py", line 14, in <module>
    import gevent
ModuleNotFoundError: No module named 'gevent'

During handling of the above exception, another exception occurred:

Traceback (most recent call last):
  File "/usr/lib/python3/dist-packages/gunicorn/util.py", line 99, in load_class
    mod = importlib.import_module('.'.join(components))
  File "/usr/lib/python3.8/importlib/__init__.py", line 127, in import_module
    return _bootstrap._gcd_import(name[level:], package, level)
  File "<frozen importlib._bootstrap>", line 1014, in _gcd_import
  File "<frozen importlib._bootstrap>", line 991, in _find_and_load
  File "<frozen importlib._bootstrap>", line 975, in _find_and_load_unlocked
  File "<frozen importlib._bootstrap>", line 671, in _load_unlocked
  File "<frozen importlib._bootstrap_external>", line 848, in exec_module
  File "<frozen importlib._bootstrap>", line 219, in _call_with_frames_removed
  File "/usr/lib/python3/dist-packages/gunicorn/workers/ggevent.py", line 16, in <module>
    raise RuntimeError("gevent worker requires gevent 1.4 or higher")
RuntimeError: gevent worker requires gevent 1.4 or higher
]


Error: class uri 'gevent' invalid or not found: 

[Traceback (most recent call last):
  File "/usr/lib/python3/dist-packages/gunicorn/workers/ggevent.py", line 14, in <module>
    import gevent
ModuleNotFoundError: No module named 'gevent'

During handling of the above exception, another exception occurred:

Traceback (most recent call last):
  File "/usr/lib/python3/dist-packages/gunicorn/util.py", line 99, in load_class
    mod = importlib.import_module('.'.join(components))
  File "/usr/lib/python3.8/importlib/__init__.py", line 127, in import_module
    return _bootstrap._gcd_import(name[level:], package, level)
  File "<frozen importlib._bootstrap>", line 1014, in _gcd_import
  File "<frozen importlib._bootstrap>", line 991, in _find_and_load
  File "<frozen importlib._bootstrap>", line 975, in _find_and_load_unlocked
  File "<frozen importlib._bootstrap>", line 671, in _load_unlocked
  File "<frozen importlib._bootstrap_external>", line 848, in exec_module
  File "<frozen importlib._bootstrap>", line 219, in _call_with_frames_removed
  File "/usr/lib/python3/dist-packages/gunicorn/workers/ggevent.py", line 16, in <module>
    raise RuntimeError("gevent worker requires gevent 1.4 or higher")
RuntimeError: gevent worker requires gevent 1.4 or higher
]


Error: class uri 'gevent' invalid or not found: 

[Traceback (most recent call last):
  File "/usr/lib/python3/dist-packages/gunicorn/workers/ggevent.py", line 14, in <module>
    import gevent
ModuleNotFoundError: No module named 'gevent'

During handling of the above exception, another exception occurred:

Traceback (most recent call last):
  File "/usr/lib/python3/dist-packages/gunicorn/util.py", line 99, in load_class
    mod = importlib.import_module('.'.join(components))
  File "/usr/lib/python3.8/importlib/__init__.py", line 127, in import_module
    return _bootstrap._gcd_import(name[level:], package, level)
  File "<frozen importlib._bootstrap>", line 1014, in _gcd_import
  File "<frozen importlib._bootstrap>", line 991, in _find_and_load
  File "<frozen importlib._bootstrap>", line 975, in _find_and_load_unlocked
  File "<frozen importlib._bootstrap>", line 671, in _load_unlocked
  File "<frozen importlib._bootstrap_external>", line 848, in exec_module
  File "<frozen importlib._bootstrap>", line 219, in _call_with_frames_removed
  File "/usr/lib/python3/dist-packages/gunicorn/workers/ggevent.py", line 16, in <module>
    raise RuntimeError("gevent worker requires gevent 1.4 or higher")
RuntimeError: gevent worker requires gevent 1.4 or higher
]


Error: class uri 'gevent' invalid or not found: 

[Traceback (most recent call last):
  File "/usr/lib/python3/dist-packages/gunicorn/workers/ggevent.py", line 14, in <module>
    import gevent
ModuleNotFoundError: No module named 'gevent'

During handling of the above exception, another exception occurred:

Traceback (most recent call last):
  File "/usr/lib/python3/dist-packages/gunicorn/util.py", line 99, in load_class
    mod = importlib.import_module('.'.join(components))
  File "/usr/lib/python3.8/importlib/__init__.py", line 127, in import_module
    return _bootstrap._gcd_import(name[level:], package, level)
  File "<frozen importlib._bootstrap>", line 1014, in _gcd_import
  File "<frozen importlib._bootstrap>", line 991, in _find_and_load
  File "<frozen importlib._bootstrap>", line 975, in _find_and_load_unlocked
  File "<frozen importlib._bootstrap>", line 671, in _load_unlocked
  File "<frozen importlib._bootstrap_external>", line 848, in exec_module
  File "<frozen importlib._bootstrap>", line 219, in _call_with_frames_removed
  File "/usr/lib/python3/dist-packages/gunicorn/workers/ggevent.py", line 16, in <module>
    raise RuntimeError("gevent worker requires gevent 1.4 or higher")
RuntimeError: gevent worker requires gevent 1.4 or higher
]


Error: class uri 'gevent' invalid or not found: 

[Traceback (most recent call last):
  File "/usr/lib/python3/dist-packages/gunicorn/workers/ggevent.py", line 14, in <module>
    import gevent
ModuleNotFoundError: No module named 'gevent'

During handling of the above exception, another exception occurred:

Traceback (most recent call last):
  File "/usr/lib/python3/dist-packages/gunicorn/util.py", line 99, in load_class
    mod = importlib.import_module('.'.join(components))
  File "/usr/lib/python3.8/importlib/__init__.py", line 127, in import_module
    return _bootstrap._gcd_import(name[level:], package, level)
  File "<frozen importlib._bootstrap>", line 1014, in _gcd_import
  File "<frozen importlib._bootstrap>", line 991, in _find_and_load
  File "<frozen importlib._bootstrap>", line 975, in _find_and_load_unlocked
  File "<frozen importlib._bootstrap>", line 671, in _load_unlocked
  File "<frozen importlib._bootstrap_external>", line 848, in exec_module
  File "<frozen importlib._bootstrap>", line 219, in _call_with_frames_removed
  File "/usr/lib/python3/dist-packages/gunicorn/workers/ggevent.py", line 16, in <module>
    raise RuntimeError("gevent worker requires gevent 1.4 or higher")
RuntimeError: gevent worker requires gevent 1.4 or higher
]


Error: class uri 'gevent' invalid or not found: 

[Traceback (most recent call last):
  File "/usr/lib/python3/dist-packages/gunicorn/workers/ggevent.py", line 14, in <module>
    import gevent
ModuleNotFoundError: No module named 'gevent'

During handling of the above exception, another exception occurred:

Traceback (most recent call last):
  File "/usr/lib/python3/dist-packages/gunicorn/util.py", line 99, in load_class
    mod = importlib.import_module('.'.join(components))
  File "/usr/lib/python3.8/importlib/__init__.py", line 127, in import_module
    return _bootstrap._gcd_import(name[level:], package, level)
  File "<frozen importlib._bootstrap>", line 1014, in _gcd_import
  File "<frozen importlib._bootstrap>", line 991, in _find_and_load
  File "<frozen importlib._bootstrap>", line 975, in _find_and_load_unlocked
  File "<frozen importlib._bootstrap>", line 671, in _load_unlocked
  File "<frozen importlib._bootstrap_external>", line 848, in exec_module
  File "<frozen importlib._bootstrap>", line 219, in _call_with_frames_removed
  File "/usr/lib/python3/dist-packages/gunicorn/workers/ggevent.py", line 16, in <module>
    raise RuntimeError("gevent worker requires gevent 1.4 or higher")
RuntimeError: gevent worker requires gevent 1.4 or higher
]


Error: class uri 'gevent' invalid or not found: 

[Traceback (most recent call last):
  File "/usr/lib/python3/dist-packages/gunicorn/workers/ggevent.py", line 14, in <module>
    import gevent
ModuleNotFoundError: No module named 'gevent'

During handling of the above exception, another exception occurred:

Traceback (most recent call last):
  File "/usr/lib/python3/dist-packages/gunicorn/util.py", line 99, in load_class
    mod = importlib.import_module('.'.join(components))
  File "/usr/lib/python3.8/importlib/__init__.py", line 127, in import_module
    return _bootstrap._gcd_import(name[level:], package, level)
  File "<frozen importlib._bootstrap>", line 1014, in _gcd_import
  File "<frozen importlib._bootstrap>", line 991, in _find_and_load
  File "<frozen importlib._bootstrap>", line 975, in _find_and_load_unlocked
  File "<frozen importlib._bootstrap>", line 671, in _load_unlocked
  File "<frozen importlib._bootstrap_external>", line 848, in exec_module
  File "<frozen importlib._bootstrap>", line 219, in _call_with_frames_removed
  File "/usr/lib/python3/dist-packages/gunicorn/workers/ggevent.py", line 16, in <module>
    raise RuntimeError("gevent worker requires gevent 1.4 or higher")
RuntimeError: gevent worker requires gevent 1.4 or higher
]


Error: class uri 'gevent' invalid or not found: 

[Traceback (most recent call last):
  File "/usr/lib/python3/dist-packages/gunicorn/workers/ggevent.py", line 14, in <module>
    import gevent
ModuleNotFoundError: No module named 'gevent'

During handling of the above exception, another exception occurred:

Traceback (most recent call last):
  File "/usr/lib/python3/dist-packages/gunicorn/util.py", line 99, in load_class
    mod = importlib.import_module('.'.join(components))
  File "/usr/lib/python3.8/importlib/__init__.py", line 127, in import_module
    return _bootstrap._gcd_import(name[level:], package, level)
  File "<frozen importlib._bootstrap>", line 1014, in _gcd_import
  File "<frozen importlib._bootstrap>", line 991, in _find_and_load
  File "<frozen importlib._bootstrap>", line 975, in _find_and_load_unlocked
  File "<frozen importlib._bootstrap>", line 671, in _load_unlocked
  File "<frozen importlib._bootstrap_external>", line 848, in exec_module
  File "<frozen importlib._bootstrap>", line 219, in _call_with_frames_removed
  File "/usr/lib/python3/dist-packages/gunicorn/workers/ggevent.py", line 16, in <module>
    raise RuntimeError("gevent worker requires gevent 1.4 or higher")
RuntimeError: gevent worker requires gevent 1.4 or higher
]


Error: class uri 'gevent' invalid or not found: 

[Traceback (most recent call last):
  File "/usr/lib/python3/dist-packages/gunicorn/workers/ggevent.py", line 14, in <module>
    import gevent
ModuleNotFoundError: No module named 'gevent'

During handling of the above exception, another exception occurred:

Traceback (most recent call last):
  File "/usr/lib/python3/dist-packages/gunicorn/util.py", line 99, in load_class
    mod = importlib.import_module('.'.join(components))
  File "/usr/lib/python3.8/importlib/__init__.py", line 127, in import_module
    return _bootstrap._gcd_import(name[level:], package, level)
  File "<frozen importlib._bootstrap>", line 1014, in _gcd_import
  File "<frozen importlib._bootstrap>", line 991, in _find_and_load
  File "<frozen importlib._bootstrap>", line 975, in _find_and_load_unlocked
  File "<frozen importlib._bootstrap>", line 671, in _load_unlocked
  File "<frozen importlib._bootstrap_external>", line 848, in exec_module
  File "<frozen importlib._bootstrap>", line 219, in _call_with_frames_removed
  File "/usr/lib/python3/dist-packages/gunicorn/workers/ggevent.py", line 16, in <module>
    raise RuntimeError("gevent worker requires gevent 1.4 or higher")
RuntimeError: gevent worker requires gevent 1.4 or higher
]


Error: class uri 'gevent' invalid or not found: 

[Traceback (most recent call last):
  File "/usr/lib/python3/dist-packages/gunicorn/workers/ggevent.py", line 14, in <module>
    import gevent
ModuleNotFoundError: No module named 'gevent'

During handling of the above exception, another exception occurred:

Traceback (most recent call last):
  File "/usr/lib/python3/dist-packages/gunicorn/util.py", line 99, in load_class
    mod = importlib.import_module('.'.join(components))
  File "/usr/lib/python3.8/importlib/__init__.py", line 127, in import_module
    return _bootstrap._gcd_import(name[level:], package, level)
  File "<frozen importlib._bootstrap>", line 1014, in _gcd_import
  File "<frozen importlib._bootstrap>", line 991, in _find_and_load
  File "<frozen importlib._bootstrap>", line 975, in _find_and_load_unlocked
  File "<frozen importlib._bootstrap>", line 671, in _load_unlocked
  File "<frozen importlib._bootstrap_external>", line 848, in exec_module
  File "<frozen importlib._bootstrap>", line 219, in _call_with_frames_removed
  File "/usr/lib/python3/dist-packages/gunicorn/workers/ggevent.py", line 16, in <module>
    raise RuntimeError("gevent worker requires gevent 1.4 or higher")
RuntimeError: gevent worker requires gevent 1.4 or higher
]


Error: class uri 'gevent' invalid or not found: 

[Traceback (most recent call last):
  File "/usr/lib/python3/dist-packages/gunicorn/workers/ggevent.py", line 14, in <module>
    import gevent
ModuleNotFoundError: No module named 'gevent'

During handling of the above exception, another exception occurred:

Traceback (most recent call last):
  File "/usr/lib/python3/dist-packages/gunicorn/util.py", line 99, in load_class
    mod = importlib.import_module('.'.join(components))
  File "/usr/lib/python3.8/importlib/__init__.py", line 127, in import_module
    return _bootstrap._gcd_import(name[level:], package, level)
  File "<frozen importlib._bootstrap>", line 1014, in _gcd_import
  File "<frozen importlib._bootstrap>", line 991, in _find_and_load
  File "<frozen importlib._bootstrap>", line 975, in _find_and_load_unlocked
  File "<frozen importlib._bootstrap>", line 671, in _load_unlocked
  File "<frozen importlib._bootstrap_external>", line 848, in exec_module
  File "<frozen importlib._bootstrap>", line 219, in _call_with_frames_removed
  File "/usr/lib/python3/dist-packages/gunicorn/workers/ggevent.py", line 16, in <module>
    raise RuntimeError("gevent worker requires gevent 1.4 or higher")
RuntimeError: gevent worker requires gevent 1.4 or higher
]


Error: class uri 'gevent' invalid or not found: 

[Traceback (most recent call last):
  File "/usr/lib/python3/dist-packages/gunicorn/workers/ggevent.py", line 14, in <module>
    import gevent
ModuleNotFoundError: No module named 'gevent'

During handling of the above exception, another exception occurred:

Traceback (most recent call last):
  File "/usr/lib/python3/dist-packages/gunicorn/util.py", line 99, in load_class
    mod = importlib.import_module('.'.join(components))
  File "/usr/lib/python3.8/importlib/__init__.py", line 127, in import_module
    return _bootstrap._gcd_import(name[level:], package, level)
  File "<frozen importlib._bootstrap>", line 1014, in _gcd_import
  File "<frozen importlib._bootstrap>", line 991, in _find_and_load
  File "<frozen importlib._bootstrap>", line 975, in _find_and_load_unlocked
  File "<frozen importlib._bootstrap>", line 671, in _load_unlocked
  File "<frozen importlib._bootstrap_external>", line 848, in exec_module
  File "<frozen importlib._bootstrap>", line 219, in _call_with_frames_removed
  File "/usr/lib/python3/dist-packages/gunicorn/workers/ggevent.py", line 16, in <module>
    raise RuntimeError("gevent worker requires gevent 1.4 or higher")
RuntimeError: gevent worker requires gevent 1.4 or higher
]


Error: class uri 'gevent' invalid or not found: 

[Traceback (most recent call last):
  File "/usr/lib/python3/dist-packages/gunicorn/workers/ggevent.py", line 14, in <module>
    import gevent
ModuleNotFoundError: No module named 'gevent'

During handling of the above exception, another exception occurred:

Traceback (most recent call last):
  File "/usr/lib/python3/dist-packages/gunicorn/util.py", line 99, in load_class
    mod = importlib.import_module('.'.join(components))
  File "/usr/lib/python3.8/importlib/__init__.py", line 127, in import_module
    return _bootstrap._gcd_import(name[level:], package, level)
  File "<frozen importlib._bootstrap>", line 1014, in _gcd_import
  File "<frozen importlib._bootstrap>", line 991, in _find_and_load
  File "<frozen importlib._bootstrap>", line 975, in _find_and_load_unlocked
  File "<frozen importlib._bootstrap>", line 671, in _load_unlocked
  File "<frozen importlib._bootstrap_external>", line 848, in exec_module
  File "<frozen importlib._bootstrap>", line 219, in _call_with_frames_removed
  File "/usr/lib/python3/dist-packages/gunicorn/workers/ggevent.py", line 16, in <module>
    raise RuntimeError("gevent worker requires gevent 1.4 or higher")
RuntimeError: gevent worker requires gevent 1.4 or higher
]


Error: class uri 'gevent' invalid or not found: 

[Traceback (most recent call last):
  File "/usr/lib/python3/dist-packages/gunicorn/workers/ggevent.py", line 14, in <module>
    import gevent
ModuleNotFoundError: No module named 'gevent'

During handling of the above exception, another exception occurred:

Traceback (most recent call last):
  File "/usr/lib/python3/dist-packages/gunicorn/util.py", line 99, in load_class
    mod = importlib.import_module('.'.join(components))
  File "/usr/lib/python3.8/importlib/__init__.py", line 127, in import_module
    return _bootstrap._gcd_import(name[level:], package, level)
  File "<frozen importlib._bootstrap>", line 1014, in _gcd_import
  File "<frozen importlib._bootstrap>", line 991, in _find_and_load
  File "<frozen importlib._bootstrap>", line 975, in _find_and_load_unlocked
  File "<frozen importlib._bootstrap>", line 671, in _load_unlocked
  File "<frozen importlib._bootstrap_external>", line 848, in exec_module
  File "<frozen importlib._bootstrap>", line 219, in _call_with_frames_removed
  File "/usr/lib/python3/dist-packages/gunicorn/workers/ggevent.py", line 16, in <module>
    raise RuntimeError("gevent worker requires gevent 1.4 or higher")
RuntimeError: gevent worker requires gevent 1.4 or higher
]


Error: class uri 'gevent' invalid or not found: 

[Traceback (most recent call last):
  File "/usr/lib/python3/dist-packages/gunicorn/workers/ggevent.py", line 14, in <module>
    import gevent
ModuleNotFoundError: No module named 'gevent'

During handling of the above exception, another exception occurred:

Traceback (most recent call last):
  File "/usr/lib/python3/dist-packages/gunicorn/util.py", line 99, in load_class
    mod = importlib.import_module('.'.join(components))
  File "/usr/lib/python3.8/importlib/__init__.py", line 127, in import_module
    return _bootstrap._gcd_import(name[level:], package, level)
  File "<frozen importlib._bootstrap>", line 1014, in _gcd_import
  File "<frozen importlib._bootstrap>", line 991, in _find_and_load
  File "<frozen importlib._bootstrap>", line 975, in _find_and_load_unlocked
  File "<frozen importlib._bootstrap>", line 671, in _load_unlocked
  File "<frozen importlib._bootstrap_external>", line 848, in exec_module
  File "<frozen importlib._bootstrap>", line 219, in _call_with_frames_removed
  File "/usr/lib/python3/dist-packages/gunicorn/workers/ggevent.py", line 16, in <module>
    raise RuntimeError("gevent worker requires gevent 1.4 or higher")
RuntimeError: gevent worker requires gevent 1.4 or higher
]


Error: class uri 'gevent' invalid or not found: 

[Traceback (most recent call last):
  File "/usr/lib/python3/dist-packages/gunicorn/workers/ggevent.py", line 14, in <module>
    import gevent
ModuleNotFoundError: No module named 'gevent'

During handling of the above exception, another exception occurred:

Traceback (most recent call last):
  File "/usr/lib/python3/dist-packages/gunicorn/util.py", line 99, in load_class
    mod = importlib.import_module('.'.join(components))
  File "/usr/lib/python3.8/importlib/__init__.py", line 127, in import_module
    return _bootstrap._gcd_import(name[level:], package, level)
  File "<frozen importlib._bootstrap>", line 1014, in _gcd_import
  File "<frozen importlib._bootstrap>", line 991, in _find_and_load
  File "<frozen importlib._bootstrap>", line 975, in _find_and_load_unlocked
  File "<frozen importlib._bootstrap>", line 671, in _load_unlocked
  File "<frozen importlib._bootstrap_external>", line 848, in exec_module
  File "<frozen importlib._bootstrap>", line 219, in _call_with_frames_removed
  File "/usr/lib/python3/dist-packages/gunicorn/workers/ggevent.py", line 16, in <module>
    raise RuntimeError("gevent worker requires gevent 1.4 or higher")
RuntimeError: gevent worker requires gevent 1.4 or higher
]


Error: class uri 'gevent' invalid or not found: 

[Traceback (most recent call last):
  File "/usr/lib/python3/dist-packages/gunicorn/workers/ggevent.py", line 14, in <module>
    import gevent
ModuleNotFoundError: No module named 'gevent'

During handling of the above exception, another exception occurred:

Traceback (most recent call last):
  File "/usr/lib/python3/dist-packages/gunicorn/util.py", line 99, in load_class
    mod = importlib.import_module('.'.join(components))
  File "/usr/lib/python3.8/importlib/__init__.py", line 127, in import_module
    return _bootstrap._gcd_import(name[level:], package, level)
  File "<frozen importlib._bootstrap>", line 1014, in _gcd_import
  File "<frozen importlib._bootstrap>", line 991, in _find_and_load
  File "<frozen importlib._bootstrap>", line 975, in _find_and_load_unlocked
  File "<frozen importlib._bootstrap>", line 671, in _load_unlocked
  File "<frozen importlib._bootstrap_external>", line 848, in exec_module
  File "<frozen importlib._bootstrap>", line 219, in _call_with_frames_removed
  File "/usr/lib/python3/dist-packages/gunicorn/workers/ggevent.py", line 16, in <module>
    raise RuntimeError("gevent worker requires gevent 1.4 or higher")
RuntimeError: gevent worker requires gevent 1.4 or higher
]


Error: class uri 'gevent' invalid or not found: 

[Traceback (most recent call last):
  File "/usr/lib/python3/dist-packages/gunicorn/workers/ggevent.py", line 14, in <module>
    import gevent
ModuleNotFoundError: No module named 'gevent'

During handling of the above exception, another exception occurred:

Traceback (most recent call last):
  File "/usr/lib/python3/dist-packages/gunicorn/util.py", line 99, in load_class
    mod = importlib.import_module('.'.join(components))
  File "/usr/lib/python3.8/importlib/__init__.py", line 127, in import_module
    return _bootstrap._gcd_import(name[level:], package, level)
  File "<frozen importlib._bootstrap>", line 1014, in _gcd_import
  File "<frozen importlib._bootstrap>", line 991, in _find_and_load
  File "<frozen importlib._bootstrap>", line 975, in _find_and_load_unlocked
  File "<frozen importlib._bootstrap>", line 671, in _load_unlocked
  File "<frozen importlib._bootstrap_external>", line 848, in exec_module
  File "<frozen importlib._bootstrap>", line 219, in _call_with_frames_removed
  File "/usr/lib/python3/dist-packages/gunicorn/workers/ggevent.py", line 16, in <module>
    raise RuntimeError("gevent worker requires gevent 1.4 or higher")
RuntimeError: gevent worker requires gevent 1.4 or higher
]


Error: class uri 'gevent' invalid or not found: 

[Traceback (most recent call last):
  File "/usr/lib/python3/dist-packages/gunicorn/workers/ggevent.py", line 14, in <module>
    import gevent
ModuleNotFoundError: No module named 'gevent'

During handling of the above exception, another exception occurred:

Traceback (most recent call last):
  File "/usr/lib/python3/dist-packages/gunicorn/util.py", line 99, in load_class
    mod = importlib.import_module('.'.join(components))
  File "/usr/lib/python3.8/importlib/__init__.py", line 127, in import_module
    return _bootstrap._gcd_import(name[level:], package, level)
  File "<frozen importlib._bootstrap>", line 1014, in _gcd_import
  File "<frozen importlib._bootstrap>", line 991, in _find_and_load
  File "<frozen importlib._bootstrap>", line 975, in _find_and_load_unlocked
  File "<frozen importlib._bootstrap>", line 671, in _load_unlocked
  File "<frozen importlib._bootstrap_external>", line 848, in exec_module
  File "<frozen importlib._bootstrap>", line 219, in _call_with_frames_removed
  File "/usr/lib/python3/dist-packages/gunicorn/workers/ggevent.py", line 16, in <module>
    raise RuntimeError("gevent worker requires gevent 1.4 or higher")
RuntimeError: gevent worker requires gevent 1.4 or higher
]

Using cache found in /root/.cache/torch/hub/snakers4_silero-vad_master
/opt/anaconda3/envs/si-dev/lib/python3.8/site-packages/numpy/core/getlimits.py:499: UserWarning: The value of the smallest subnormal for <class 'numpy.float64'> type is zero.
  setattr(self, word, getattr(machar, word).flat[0])
/opt/anaconda3/envs/si-dev/lib/python3.8/site-packages/numpy/core/getlimits.py:89: UserWarning: The value of the smallest subnormal for <class 'numpy.float64'> type is zero.
  return self._float_to_str(self.smallest_subnormal)
/opt/anaconda3/envs/si-dev/lib/python3.8/site-packages/numpy/core/getlimits.py:499: UserWarning: The value of the smallest subnormal for <class 'numpy.float32'> type is zero.
  setattr(self, word, getattr(machar, word).flat[0])
/opt/anaconda3/envs/si-dev/lib/python3.8/site-packages/numpy/core/getlimits.py:89: UserWarning: The value of the smallest subnormal for <class 'numpy.float32'> type is zero.
  return self._float_to_str(self.smallest_subnormal)
/opt/anaconda3/envs/si-dev/lib/python3.8/site-packages/huggingface_hub/utils/_deprecation.py:39: FutureWarning: Pass library_name=False as keyword args. From version 0.8 passing these as positional arguments will result in an error
  warnings.warn(
/opt/anaconda3/envs/si-dev/lib/python3.8/site-packages/flask_sqlalchemy/__init__.py:872: FSADeprecationWarning: SQLALCHEMY_TRACK_MODIFICATIONS adds significant overhead and will be disabled by default in the future.  Set it to True or False to suppress this warning.
  warnings.warn(FSADeprecationWarning(
/opt/anaconda3/envs/si-dev/lib/python3.8/site-packages/flask_sqlalchemy/__init__.py:872: FSADeprecationWarning: SQLALCHEMY_TRACK_MODIFICATIONS adds significant overhead and will be disabled by default in the future.  Set it to True or False to suppress this warning.
  warnings.warn(FSADeprecationWarning(
下载完成
'>' not supported between instances of 'tuple' and 'int'
INSERT INTO log (phone, action_type,time,err_type, message) VALUES ('15151832012', '2', curtime(),'3', '文件读取失败');
Using cache found in /root/.cache/torch/hub/snakers4_silero-vad_master
/opt/anaconda3/envs/si-dev/lib/python3.8/site-packages/numpy/core/getlimits.py:499: UserWarning: The value of the smallest subnormal for <class 'numpy.float64'> type is zero.
  setattr(self, word, getattr(machar, word).flat[0])
/opt/anaconda3/envs/si-dev/lib/python3.8/site-packages/numpy/core/getlimits.py:89: UserWarning: The value of the smallest subnormal for <class 'numpy.float64'> type is zero.
  return self._float_to_str(self.smallest_subnormal)
/opt/anaconda3/envs/si-dev/lib/python3.8/site-packages/numpy/core/getlimits.py:499: UserWarning: The value of the smallest subnormal for <class 'numpy.float32'> type is zero.
  setattr(self, word, getattr(machar, word).flat[0])
/opt/anaconda3/envs/si-dev/lib/python3.8/site-packages/numpy/core/getlimits.py:89: UserWarning: The value of the smallest subnormal for <class 'numpy.float32'> type is zero.
  return self._float_to_str(self.smallest_subnormal)
/opt/anaconda3/envs/si-dev/lib/python3.8/site-packages/huggingface_hub/utils/_deprecation.py:39: FutureWarning: Pass library_name=False as keyword args. From version 0.8 passing these as positional arguments will result in an error
  warnings.warn(
/opt/anaconda3/envs/si-dev/lib/python3.8/site-packages/flask_sqlalchemy/__init__.py:872: FSADeprecationWarning: SQLALCHEMY_TRACK_MODIFICATIONS adds significant overhead and will be disabled by default in the future.  Set it to True or False to suppress this warning.
  warnings.warn(FSADeprecationWarning(
/opt/anaconda3/envs/si-dev/lib/python3.8/site-packages/flask_sqlalchemy/__init__.py:872: FSADeprecationWarning: SQLALCHEMY_TRACK_MODIFICATIONS adds significant overhead and will be disabled by default in the future.  Set it to True or False to suppress this warning.
  warnings.warn(FSADeprecationWarning(
下载完成
'>' not supported between instances of 'tuple' and 'int'
INSERT INTO log (phone, action_type,time,err_type, message) VALUES ('15151832012', '2', curtime(),'3', '文件读取失败');
Using cache found in /root/.cache/torch/hub/snakers4_silero-vad_master
/opt/anaconda3/envs/si-dev/lib/python3.8/site-packages/numpy/core/getlimits.py:499: UserWarning: The value of the smallest subnormal for <class 'numpy.float64'> type is zero.
  setattr(self, word, getattr(machar, word).flat[0])
/opt/anaconda3/envs/si-dev/lib/python3.8/site-packages/numpy/core/getlimits.py:89: UserWarning: The value of the smallest subnormal for <class 'numpy.float64'> type is zero.
  return self._float_to_str(self.smallest_subnormal)
/opt/anaconda3/envs/si-dev/lib/python3.8/site-packages/numpy/core/getlimits.py:499: UserWarning: The value of the smallest subnormal for <class 'numpy.float32'> type is zero.
  setattr(self, word, getattr(machar, word).flat[0])
/opt/anaconda3/envs/si-dev/lib/python3.8/site-packages/numpy/core/getlimits.py:89: UserWarning: The value of the smallest subnormal for <class 'numpy.float32'> type is zero.
  return self._float_to_str(self.smallest_subnormal)
/opt/anaconda3/envs/si-dev/lib/python3.8/site-packages/huggingface_hub/utils/_deprecation.py:39: FutureWarning: Pass library_name=False as keyword args. From version 0.8 passing these as positional arguments will result in an error
  warnings.warn(
/opt/anaconda3/envs/si-dev/lib/python3.8/site-packages/flask_sqlalchemy/__init__.py:872: FSADeprecationWarning: SQLALCHEMY_TRACK_MODIFICATIONS adds significant overhead and will be disabled by default in the future.  Set it to True or False to suppress this warning.
  warnings.warn(FSADeprecationWarning(
/opt/anaconda3/envs/si-dev/lib/python3.8/site-packages/flask_sqlalchemy/__init__.py:872: FSADeprecationWarning: SQLALCHEMY_TRACK_MODIFICATIONS adds significant overhead and will be disabled by default in the future.  Set it to True or False to suppress this warning.
  warnings.warn(FSADeprecationWarning(
Using cache found in /root/.cache/torch/hub/snakers4_silero-vad_master
/opt/anaconda3/envs/si-dev/lib/python3.8/site-packages/numpy/core/getlimits.py:499: UserWarning: The value of the smallest subnormal for <class 'numpy.float64'> type is zero.
  setattr(self, word, getattr(machar, word).flat[0])
/opt/anaconda3/envs/si-dev/lib/python3.8/site-packages/numpy/core/getlimits.py:89: UserWarning: The value of the smallest subnormal for <class 'numpy.float64'> type is zero.
  return self._float_to_str(self.smallest_subnormal)
/opt/anaconda3/envs/si-dev/lib/python3.8/site-packages/numpy/core/getlimits.py:499: UserWarning: The value of the smallest subnormal for <class 'numpy.float32'> type is zero.
  setattr(self, word, getattr(machar, word).flat[0])
/opt/anaconda3/envs/si-dev/lib/python3.8/site-packages/numpy/core/getlimits.py:89: UserWarning: The value of the smallest subnormal for <class 'numpy.float32'> type is zero.
  return self._float_to_str(self.smallest_subnormal)
/opt/anaconda3/envs/si-dev/lib/python3.8/site-packages/huggingface_hub/utils/_deprecation.py:39: FutureWarning: Pass library_name=False as keyword args. From version 0.8 passing these as positional arguments will result in an error
  warnings.warn(
/opt/anaconda3/envs/si-dev/lib/python3.8/site-packages/flask_sqlalchemy/__init__.py:872: FSADeprecationWarning: SQLALCHEMY_TRACK_MODIFICATIONS adds significant overhead and will be disabled by default in the future.  Set it to True or False to suppress this warning.
  warnings.warn(FSADeprecationWarning(
/opt/anaconda3/envs/si-dev/lib/python3.8/site-packages/flask_sqlalchemy/__init__.py:872: FSADeprecationWarning: SQLALCHEMY_TRACK_MODIFICATIONS adds significant overhead and will be disabled by default in the future.  Set it to True or False to suppress this warning.
  warnings.warn(FSADeprecationWarning(
Using cache found in /root/.cache/torch/hub/snakers4_silero-vad_master
/opt/anaconda3/envs/si-dev/lib/python3.8/site-packages/numpy/core/getlimits.py:499: UserWarning: The value of the smallest subnormal for <class 'numpy.float64'> type is zero.
  setattr(self, word, getattr(machar, word).flat[0])
/opt/anaconda3/envs/si-dev/lib/python3.8/site-packages/numpy/core/getlimits.py:89: UserWarning: The value of the smallest subnormal for <class 'numpy.float64'> type is zero.
  return self._float_to_str(self.smallest_subnormal)
/opt/anaconda3/envs/si-dev/lib/python3.8/site-packages/numpy/core/getlimits.py:499: UserWarning: The value of the smallest subnormal for <class 'numpy.float32'> type is zero.
  setattr(self, word, getattr(machar, word).flat[0])
/opt/anaconda3/envs/si-dev/lib/python3.8/site-packages/numpy/core/getlimits.py:89: UserWarning: The value of the smallest subnormal for <class 'numpy.float32'> type is zero.
  return self._float_to_str(self.smallest_subnormal)
/opt/anaconda3/envs/si-dev/lib/python3.8/site-packages/huggingface_hub/utils/_deprecation.py:39: FutureWarning: Pass library_name=False as keyword args. From version 0.8 passing these as positional arguments will result in an error
  warnings.warn(
/opt/anaconda3/envs/si-dev/lib/python3.8/site-packages/flask_sqlalchemy/__init__.py:872: FSADeprecationWarning: SQLALCHEMY_TRACK_MODIFICATIONS adds significant overhead and will be disabled by default in the future.  Set it to True or False to suppress this warning.
  warnings.warn(FSADeprecationWarning(
/opt/anaconda3/envs/si-dev/lib/python3.8/site-packages/flask_sqlalchemy/__init__.py:872: FSADeprecationWarning: SQLALCHEMY_TRACK_MODIFICATIONS adds significant overhead and will be disabled by default in the future.  Set it to True or False to suppress this warning.
  warnings.warn(FSADeprecationWarning(
Using cache found in /root/.cache/torch/hub/snakers4_silero-vad_master
/opt/anaconda3/envs/si-dev/lib/python3.8/site-packages/numpy/core/getlimits.py:499: UserWarning: The value of the smallest subnormal for <class 'numpy.float64'> type is zero.
  setattr(self, word, getattr(machar, word).flat[0])
/opt/anaconda3/envs/si-dev/lib/python3.8/site-packages/numpy/core/getlimits.py:89: UserWarning: The value of the smallest subnormal for <class 'numpy.float64'> type is zero.
  return self._float_to_str(self.smallest_subnormal)
/opt/anaconda3/envs/si-dev/lib/python3.8/site-packages/numpy/core/getlimits.py:499: UserWarning: The value of the smallest subnormal for <class 'numpy.float32'> type is zero.
  setattr(self, word, getattr(machar, word).flat[0])
/opt/anaconda3/envs/si-dev/lib/python3.8/site-packages/numpy/core/getlimits.py:89: UserWarning: The value of the smallest subnormal for <class 'numpy.float32'> type is zero.
  return self._float_to_str(self.smallest_subnormal)
/opt/anaconda3/envs/si-dev/lib/python3.8/site-packages/huggingface_hub/utils/_deprecation.py:39: FutureWarning: Pass library_name=False as keyword args. From version 0.8 passing these as positional arguments will result in an error
  warnings.warn(
/opt/anaconda3/envs/si-dev/lib/python3.8/site-packages/flask_sqlalchemy/__init__.py:872: FSADeprecationWarning: SQLALCHEMY_TRACK_MODIFICATIONS adds significant overhead and will be disabled by default in the future.  Set it to True or False to suppress this warning.
  warnings.warn(FSADeprecationWarning(
/opt/anaconda3/envs/si-dev/lib/python3.8/site-packages/flask_sqlalchemy/__init__.py:872: FSADeprecationWarning: SQLALCHEMY_TRACK_MODIFICATIONS adds significant overhead and will be disabled by default in the future.  Set it to True or False to suppress this warning.
  warnings.warn(FSADeprecationWarning(
下载完成
torch.Size([480000])
INSERT INTO log (phone, action_type,time,err_type, message) VALUES ('15151832012', '2', curtime(),'2', 'Insufficient duration, the current duration is 11.782s.');
Using cache found in /root/.cache/torch/hub/snakers4_silero-vad_master
/opt/anaconda3/envs/si-dev/lib/python3.8/site-packages/numpy/core/getlimits.py:499: UserWarning: The value of the smallest subnormal for <class 'numpy.float64'> type is zero.
  setattr(self, word, getattr(machar, word).flat[0])
/opt/anaconda3/envs/si-dev/lib/python3.8/site-packages/numpy/core/getlimits.py:89: UserWarning: The value of the smallest subnormal for <class 'numpy.float64'> type is zero.
  return self._float_to_str(self.smallest_subnormal)
/opt/anaconda3/envs/si-dev/lib/python3.8/site-packages/numpy/core/getlimits.py:499: UserWarning: The value of the smallest subnormal for <class 'numpy.float32'> type is zero.
  setattr(self, word, getattr(machar, word).flat[0])
/opt/anaconda3/envs/si-dev/lib/python3.8/site-packages/numpy/core/getlimits.py:89: UserWarning: The value of the smallest subnormal for <class 'numpy.float32'> type is zero.
  return self._float_to_str(self.smallest_subnormal)
/opt/anaconda3/envs/si-dev/lib/python3.8/site-packages/huggingface_hub/utils/_deprecation.py:39: FutureWarning: Pass library_name=False as keyword args. From version 0.8 passing these as positional arguments will result in an error
  warnings.warn(
/opt/anaconda3/envs/si-dev/lib/python3.8/site-packages/flask_sqlalchemy/__init__.py:872: FSADeprecationWarning: SQLALCHEMY_TRACK_MODIFICATIONS adds significant overhead and will be disabled by default in the future.  Set it to True or False to suppress this warning.
  warnings.warn(FSADeprecationWarning(
/opt/anaconda3/envs/si-dev/lib/python3.8/site-packages/flask_sqlalchemy/__init__.py:872: FSADeprecationWarning: SQLALCHEMY_TRACK_MODIFICATIONS adds significant overhead and will be disabled by default in the future.  Set it to True or False to suppress this warning.
  warnings.warn(FSADeprecationWarning(
下载完成
torch.Size([480000])
INSERT INTO log (phone, action_type,time,err_type, message) VALUES ('15151832012', '2', curtime(),'2', 'Insufficient duration, the current duration is 11.782s.');
Using cache found in /root/.cache/torch/hub/snakers4_silero-vad_master
/opt/anaconda3/envs/si-dev/lib/python3.8/site-packages/numpy/core/getlimits.py:499: UserWarning: The value of the smallest subnormal for <class 'numpy.float64'> type is zero.
  setattr(self, word, getattr(machar, word).flat[0])
/opt/anaconda3/envs/si-dev/lib/python3.8/site-packages/numpy/core/getlimits.py:89: UserWarning: The value of the smallest subnormal for <class 'numpy.float64'> type is zero.
  return self._float_to_str(self.smallest_subnormal)
/opt/anaconda3/envs/si-dev/lib/python3.8/site-packages/numpy/core/getlimits.py:499: UserWarning: The value of the smallest subnormal for <class 'numpy.float32'> type is zero.
  setattr(self, word, getattr(machar, word).flat[0])
/opt/anaconda3/envs/si-dev/lib/python3.8/site-packages/numpy/core/getlimits.py:89: UserWarning: The value of the smallest subnormal for <class 'numpy.float32'> type is zero.
  return self._float_to_str(self.smallest_subnormal)
/opt/anaconda3/envs/si-dev/lib/python3.8/site-packages/huggingface_hub/utils/_deprecation.py:39: FutureWarning: Pass library_name=False as keyword args. From version 0.8 passing these as positional arguments will result in an error
  warnings.warn(
/opt/anaconda3/envs/si-dev/lib/python3.8/site-packages/flask_sqlalchemy/__init__.py:872: FSADeprecationWarning: SQLALCHEMY_TRACK_MODIFICATIONS adds significant overhead and will be disabled by default in the future.  Set it to True or False to suppress this warning.
  warnings.warn(FSADeprecationWarning(
/opt/anaconda3/envs/si-dev/lib/python3.8/site-packages/flask_sqlalchemy/__init__.py:872: FSADeprecationWarning: SQLALCHEMY_TRACK_MODIFICATIONS adds significant overhead and will be disabled by default in the future.  Set it to True or False to suppress this warning.
  warnings.warn(FSADeprecationWarning(
下载完成
torch.Size([480000])
INSERT INTO log (phone, action_type,time,err_type, message) VALUES ('15151832012', '2', curtime(),'2', 'Insufficient duration, the current duration is 18.98s.');
Using cache found in /root/.cache/torch/hub/snakers4_silero-vad_master
/opt/anaconda3/envs/si-dev/lib/python3.8/site-packages/numpy/core/getlimits.py:499: UserWarning: The value of the smallest subnormal for <class 'numpy.float64'> type is zero.
  setattr(self, word, getattr(machar, word).flat[0])
/opt/anaconda3/envs/si-dev/lib/python3.8/site-packages/numpy/core/getlimits.py:89: UserWarning: The value of the smallest subnormal for <class 'numpy.float64'> type is zero.
  return self._float_to_str(self.smallest_subnormal)
/opt/anaconda3/envs/si-dev/lib/python3.8/site-packages/numpy/core/getlimits.py:499: UserWarning: The value of the smallest subnormal for <class 'numpy.float32'> type is zero.
  setattr(self, word, getattr(machar, word).flat[0])
/opt/anaconda3/envs/si-dev/lib/python3.8/site-packages/numpy/core/getlimits.py:89: UserWarning: The value of the smallest subnormal for <class 'numpy.float32'> type is zero.
  return self._float_to_str(self.smallest_subnormal)
/opt/anaconda3/envs/si-dev/lib/python3.8/site-packages/huggingface_hub/utils/_deprecation.py:39: FutureWarning: Pass library_name=False as keyword args. From version 0.8 passing these as positional arguments will result in an error
  warnings.warn(
/opt/anaconda3/envs/si-dev/lib/python3.8/site-packages/flask_sqlalchemy/__init__.py:872: FSADeprecationWarning: SQLALCHEMY_TRACK_MODIFICATIONS adds significant overhead and will be disabled by default in the future.  Set it to True or False to suppress this warning.
  warnings.warn(FSADeprecationWarning(
/opt/anaconda3/envs/si-dev/lib/python3.8/site-packages/flask_sqlalchemy/__init__.py:872: FSADeprecationWarning: SQLALCHEMY_TRACK_MODIFICATIONS adds significant overhead and will be disabled by default in the future.  Set it to True or False to suppress this warning.
  warnings.warn(FSADeprecationWarning(
/home/zhaosheng/VAF-System/demo_flask/utils/preprocess.py:94: UserWarning: To copy construct from a tensor, it is recommended to use sourceTensor.clone().detach() or sourceTensor.clone().detach().requires_grad_(True), rather than torch.tensor(sourceTensor).
  tiny_wav = torch.tensor(
下载完成
torch.Size([960000])
Score:0.5787882804870605
INSERT INTO log (phone, action_type,time,err_type, message) VALUES ('15151832012', '2', curtime(),'1', 'Bad quality score:0.5787882804870605.');
下载完成
torch.Size([960000])
Score:0.5787882804870605
INSERT INTO log (phone, action_type,time,err_type, message) VALUES ('15151832012', '2', curtime(),'1', 'Bad quality score:0.5787882804870605.');
Using cache found in /root/.cache/torch/hub/snakers4_silero-vad_master
/opt/anaconda3/envs/si-dev/lib/python3.8/site-packages/numpy/core/getlimits.py:499: UserWarning: The value of the smallest subnormal for <class 'numpy.float64'> type is zero.
  setattr(self, word, getattr(machar, word).flat[0])
/opt/anaconda3/envs/si-dev/lib/python3.8/site-packages/numpy/core/getlimits.py:89: UserWarning: The value of the smallest subnormal for <class 'numpy.float64'> type is zero.
  return self._float_to_str(self.smallest_subnormal)
/opt/anaconda3/envs/si-dev/lib/python3.8/site-packages/numpy/core/getlimits.py:499: UserWarning: The value of the smallest subnormal for <class 'numpy.float32'> type is zero.
  setattr(self, word, getattr(machar, word).flat[0])
/opt/anaconda3/envs/si-dev/lib/python3.8/site-packages/numpy/core/getlimits.py:89: UserWarning: The value of the smallest subnormal for <class 'numpy.float32'> type is zero.
  return self._float_to_str(self.smallest_subnormal)
/opt/anaconda3/envs/si-dev/lib/python3.8/site-packages/huggingface_hub/utils/_deprecation.py:39: FutureWarning: Pass library_name=False as keyword args. From version 0.8 passing these as positional arguments will result in an error
  warnings.warn(
/opt/anaconda3/envs/si-dev/lib/python3.8/site-packages/flask_sqlalchemy/__init__.py:872: FSADeprecationWarning: SQLALCHEMY_TRACK_MODIFICATIONS adds significant overhead and will be disabled by default in the future.  Set it to True or False to suppress this warning.
  warnings.warn(FSADeprecationWarning(
/opt/anaconda3/envs/si-dev/lib/python3.8/site-packages/flask_sqlalchemy/__init__.py:872: FSADeprecationWarning: SQLALCHEMY_TRACK_MODIFICATIONS adds significant overhead and will be disabled by default in the future.  Set it to True or False to suppress this warning.
  warnings.warn(FSADeprecationWarning(
/home/zhaosheng/VAF-System/demo_flask/utils/preprocess.py:94: UserWarning: To copy construct from a tensor, it is recommended to use sourceTensor.clone().detach() or sourceTensor.clone().detach().requires_grad_(True), rather than torch.tensor(sourceTensor).
  tiny_wav = torch.tensor(
下载完成
Error opening '/home/zhaosheng/VAF-System/demo_flask/wavs/raw/15151832002/raw_1.wav': System error.
INSERT INTO log (phone, action_type,time,err_type, message) VALUES ('15151832012', '2', curtime(),'3', '文件读取失败');
下载完成
torch.Size([960000])
Score:0.5787882804870605
INSERT INTO log (phone, action_type,time,err_type, message) VALUES ('15151832012', '2', curtime(),'1', 'Bad quality score:0.5787882804870605.');
Using cache found in /root/.cache/torch/hub/snakers4_silero-vad_master
/opt/anaconda3/envs/si-dev/lib/python3.8/site-packages/numpy/core/getlimits.py:499: UserWarning: The value of the smallest subnormal for <class 'numpy.float64'> type is zero.
  setattr(self, word, getattr(machar, word).flat[0])
/opt/anaconda3/envs/si-dev/lib/python3.8/site-packages/numpy/core/getlimits.py:89: UserWarning: The value of the smallest subnormal for <class 'numpy.float64'> type is zero.
  return self._float_to_str(self.smallest_subnormal)
/opt/anaconda3/envs/si-dev/lib/python3.8/site-packages/numpy/core/getlimits.py:499: UserWarning: The value of the smallest subnormal for <class 'numpy.float32'> type is zero.
  setattr(self, word, getattr(machar, word).flat[0])
/opt/anaconda3/envs/si-dev/lib/python3.8/site-packages/numpy/core/getlimits.py:89: UserWarning: The value of the smallest subnormal for <class 'numpy.float32'> type is zero.
  return self._float_to_str(self.smallest_subnormal)
/opt/anaconda3/envs/si-dev/lib/python3.8/site-packages/huggingface_hub/utils/_deprecation.py:39: FutureWarning: Pass library_name=False as keyword args. From version 0.8 passing these as positional arguments will result in an error
  warnings.warn(
/opt/anaconda3/envs/si-dev/lib/python3.8/site-packages/flask_sqlalchemy/__init__.py:872: FSADeprecationWarning: SQLALCHEMY_TRACK_MODIFICATIONS adds significant overhead and will be disabled by default in the future.  Set it to True or False to suppress this warning.
  warnings.warn(FSADeprecationWarning(
/opt/anaconda3/envs/si-dev/lib/python3.8/site-packages/flask_sqlalchemy/__init__.py:872: FSADeprecationWarning: SQLALCHEMY_TRACK_MODIFICATIONS adds significant overhead and will be disabled by default in the future.  Set it to True or False to suppress this warning.
  warnings.warn(FSADeprecationWarning(
/home/zhaosheng/VAF-System/demo_flask/utils/preprocess.py:94: UserWarning: To copy construct from a tensor, it is recommended to use sourceTensor.clone().detach() or sourceTensor.clone().detach().requires_grad_(True), rather than torch.tensor(sourceTensor).
  tiny_wav = torch.tensor(
下载完成
torch.Size([960000])
Score:0.5787882804870605
INSERT INTO log (phone, action_type,time,err_type, message) VALUES ('15151832012', '2', curtime(),'1', 'Bad quality score:0.5787882804870605.');
Using cache found in /root/.cache/torch/hub/snakers4_silero-vad_master
/opt/anaconda3/envs/si-dev/lib/python3.8/site-packages/numpy/core/getlimits.py:499: UserWarning: The value of the smallest subnormal for <class 'numpy.float64'> type is zero.
  setattr(self, word, getattr(machar, word).flat[0])
/opt/anaconda3/envs/si-dev/lib/python3.8/site-packages/numpy/core/getlimits.py:89: UserWarning: The value of the smallest subnormal for <class 'numpy.float64'> type is zero.
  return self._float_to_str(self.smallest_subnormal)
/opt/anaconda3/envs/si-dev/lib/python3.8/site-packages/numpy/core/getlimits.py:499: UserWarning: The value of the smallest subnormal for <class 'numpy.float32'> type is zero.
  setattr(self, word, getattr(machar, word).flat[0])
/opt/anaconda3/envs/si-dev/lib/python3.8/site-packages/numpy/core/getlimits.py:89: UserWarning: The value of the smallest subnormal for <class 'numpy.float32'> type is zero.
  return self._float_to_str(self.smallest_subnormal)
/opt/anaconda3/envs/si-dev/lib/python3.8/site-packages/huggingface_hub/utils/_deprecation.py:39: FutureWarning: Pass library_name=False as keyword args. From version 0.8 passing these as positional arguments will result in an error
  warnings.warn(
/opt/anaconda3/envs/si-dev/lib/python3.8/site-packages/flask_sqlalchemy/__init__.py:872: FSADeprecationWarning: SQLALCHEMY_TRACK_MODIFICATIONS adds significant overhead and will be disabled by default in the future.  Set it to True or False to suppress this warning.
  warnings.warn(FSADeprecationWarning(
/opt/anaconda3/envs/si-dev/lib/python3.8/site-packages/flask_sqlalchemy/__init__.py:872: FSADeprecationWarning: SQLALCHEMY_TRACK_MODIFICATIONS adds significant overhead and will be disabled by default in the future.  Set it to True or False to suppress this warning.
  warnings.warn(FSADeprecationWarning(
下载完成
too many indices for array: array is 1-dimensional, but 2 were indexed
INSERT INTO log (phone, action_type,time,err_type, message) VALUES ('15151832012', '2', curtime(),'3', '文件读取失败');
Using cache found in /root/.cache/torch/hub/snakers4_silero-vad_master
/opt/anaconda3/envs/si-dev/lib/python3.8/site-packages/numpy/core/getlimits.py:499: UserWarning: The value of the smallest subnormal for <class 'numpy.float64'> type is zero.
  setattr(self, word, getattr(machar, word).flat[0])
/opt/anaconda3/envs/si-dev/lib/python3.8/site-packages/numpy/core/getlimits.py:89: UserWarning: The value of the smallest subnormal for <class 'numpy.float64'> type is zero.
  return self._float_to_str(self.smallest_subnormal)
/opt/anaconda3/envs/si-dev/lib/python3.8/site-packages/numpy/core/getlimits.py:499: UserWarning: The value of the smallest subnormal for <class 'numpy.float32'> type is zero.
  setattr(self, word, getattr(machar, word).flat[0])
/opt/anaconda3/envs/si-dev/lib/python3.8/site-packages/numpy/core/getlimits.py:89: UserWarning: The value of the smallest subnormal for <class 'numpy.float32'> type is zero.
  return self._float_to_str(self.smallest_subnormal)
/opt/anaconda3/envs/si-dev/lib/python3.8/site-packages/huggingface_hub/utils/_deprecation.py:39: FutureWarning: Pass library_name=False as keyword args. From version 0.8 passing these as positional arguments will result in an error
  warnings.warn(
/opt/anaconda3/envs/si-dev/lib/python3.8/site-packages/flask_sqlalchemy/__init__.py:872: FSADeprecationWarning: SQLALCHEMY_TRACK_MODIFICATIONS adds significant overhead and will be disabled by default in the future.  Set it to True or False to suppress this warning.
  warnings.warn(FSADeprecationWarning(
/opt/anaconda3/envs/si-dev/lib/python3.8/site-packages/flask_sqlalchemy/__init__.py:872: FSADeprecationWarning: SQLALCHEMY_TRACK_MODIFICATIONS adds significant overhead and will be disabled by default in the future.  Set it to True or False to suppress this warning.
  warnings.warn(FSADeprecationWarning(
/home/zhaosheng/VAF-System/demo_flask/utils/preprocess.py:94: UserWarning: To copy construct from a tensor, it is recommended to use sourceTensor.clone().detach() or sourceTensor.clone().detach().requires_grad_(True), rather than torch.tensor(sourceTensor).
  tiny_wav = torch.tensor(
下载完成
torch.Size([960000])
Score:0.5787882804870605
Using cache found in /root/.cache/torch/hub/snakers4_silero-vad_master
/opt/anaconda3/envs/si-dev/lib/python3.8/site-packages/numpy/core/getlimits.py:499: UserWarning: The value of the smallest subnormal for <class 'numpy.float64'> type is zero.
  setattr(self, word, getattr(machar, word).flat[0])
/opt/anaconda3/envs/si-dev/lib/python3.8/site-packages/numpy/core/getlimits.py:89: UserWarning: The value of the smallest subnormal for <class 'numpy.float64'> type is zero.
  return self._float_to_str(self.smallest_subnormal)
/opt/anaconda3/envs/si-dev/lib/python3.8/site-packages/numpy/core/getlimits.py:499: UserWarning: The value of the smallest subnormal for <class 'numpy.float32'> type is zero.
  setattr(self, word, getattr(machar, word).flat[0])
/opt/anaconda3/envs/si-dev/lib/python3.8/site-packages/numpy/core/getlimits.py:89: UserWarning: The value of the smallest subnormal for <class 'numpy.float32'> type is zero.
  return self._float_to_str(self.smallest_subnormal)
/opt/anaconda3/envs/si-dev/lib/python3.8/site-packages/huggingface_hub/utils/_deprecation.py:39: FutureWarning: Pass library_name=False as keyword args. From version 0.8 passing these as positional arguments will result in an error
  warnings.warn(
/opt/anaconda3/envs/si-dev/lib/python3.8/site-packages/flask_sqlalchemy/__init__.py:872: FSADeprecationWarning: SQLALCHEMY_TRACK_MODIFICATIONS adds significant overhead and will be disabled by default in the future.  Set it to True or False to suppress this warning.
  warnings.warn(FSADeprecationWarning(
/opt/anaconda3/envs/si-dev/lib/python3.8/site-packages/flask_sqlalchemy/__init__.py:872: FSADeprecationWarning: SQLALCHEMY_TRACK_MODIFICATIONS adds significant overhead and will be disabled by default in the future.  Set it to True or False to suppress this warning.
  warnings.warn(FSADeprecationWarning(
/home/zhaosheng/VAF-System/demo_flask/utils/preprocess.py:94: UserWarning: To copy construct from a tensor, it is recommended to use sourceTensor.clone().detach() or sourceTensor.clone().detach().requires_grad_(True), rather than torch.tensor(sourceTensor).
  tiny_wav = torch.tensor(
下载完成
torch.Size([960000])
Score:0.5787882804870605
下载完成
torch.Size([960000])
Score:0.5787882804870605
Using cache found in /root/.cache/torch/hub/snakers4_silero-vad_master
/opt/anaconda3/envs/si-dev/lib/python3.8/site-packages/numpy/core/getlimits.py:499: UserWarning: The value of the smallest subnormal for <class 'numpy.float64'> type is zero.
  setattr(self, word, getattr(machar, word).flat[0])
/opt/anaconda3/envs/si-dev/lib/python3.8/site-packages/numpy/core/getlimits.py:89: UserWarning: The value of the smallest subnormal for <class 'numpy.float64'> type is zero.
  return self._float_to_str(self.smallest_subnormal)
/opt/anaconda3/envs/si-dev/lib/python3.8/site-packages/numpy/core/getlimits.py:499: UserWarning: The value of the smallest subnormal for <class 'numpy.float32'> type is zero.
  setattr(self, word, getattr(machar, word).flat[0])
/opt/anaconda3/envs/si-dev/lib/python3.8/site-packages/numpy/core/getlimits.py:89: UserWarning: The value of the smallest subnormal for <class 'numpy.float32'> type is zero.
  return self._float_to_str(self.smallest_subnormal)
/opt/anaconda3/envs/si-dev/lib/python3.8/site-packages/huggingface_hub/utils/_deprecation.py:39: FutureWarning: Pass library_name=False as keyword args. From version 0.8 passing these as positional arguments will result in an error
  warnings.warn(
/opt/anaconda3/envs/si-dev/lib/python3.8/site-packages/flask_sqlalchemy/__init__.py:872: FSADeprecationWarning: SQLALCHEMY_TRACK_MODIFICATIONS adds significant overhead and will be disabled by default in the future.  Set it to True or False to suppress this warning.
  warnings.warn(FSADeprecationWarning(
/opt/anaconda3/envs/si-dev/lib/python3.8/site-packages/flask_sqlalchemy/__init__.py:872: FSADeprecationWarning: SQLALCHEMY_TRACK_MODIFICATIONS adds significant overhead and will be disabled by default in the future.  Set it to True or False to suppress this warning.
  warnings.warn(FSADeprecationWarning(
/home/zhaosheng/VAF-System/demo_flask/utils/preprocess.py:94: UserWarning: To copy construct from a tensor, it is recommended to use sourceTensor.clone().detach() or sourceTensor.clone().detach().requires_grad_(True), rather than torch.tensor(sourceTensor).
  tiny_wav = torch.tensor(
下载完成
torch.Size([960000])
Score:0.5787882804870605
Using cache found in /root/.cache/torch/hub/snakers4_silero-vad_master
/opt/anaconda3/envs/si-dev/lib/python3.8/site-packages/numpy/core/getlimits.py:499: UserWarning: The value of the smallest subnormal for <class 'numpy.float64'> type is zero.
  setattr(self, word, getattr(machar, word).flat[0])
/opt/anaconda3/envs/si-dev/lib/python3.8/site-packages/numpy/core/getlimits.py:89: UserWarning: The value of the smallest subnormal for <class 'numpy.float64'> type is zero.
  return self._float_to_str(self.smallest_subnormal)
/opt/anaconda3/envs/si-dev/lib/python3.8/site-packages/numpy/core/getlimits.py:499: UserWarning: The value of the smallest subnormal for <class 'numpy.float32'> type is zero.
  setattr(self, word, getattr(machar, word).flat[0])
/opt/anaconda3/envs/si-dev/lib/python3.8/site-packages/numpy/core/getlimits.py:89: UserWarning: The value of the smallest subnormal for <class 'numpy.float32'> type is zero.
  return self._float_to_str(self.smallest_subnormal)
/opt/anaconda3/envs/si-dev/lib/python3.8/site-packages/huggingface_hub/utils/_deprecation.py:39: FutureWarning: Pass library_name=False as keyword args. From version 0.8 passing these as positional arguments will result in an error
  warnings.warn(
/opt/anaconda3/envs/si-dev/lib/python3.8/site-packages/flask_sqlalchemy/__init__.py:872: FSADeprecationWarning: SQLALCHEMY_TRACK_MODIFICATIONS adds significant overhead and will be disabled by default in the future.  Set it to True or False to suppress this warning.
  warnings.warn(FSADeprecationWarning(
/opt/anaconda3/envs/si-dev/lib/python3.8/site-packages/flask_sqlalchemy/__init__.py:872: FSADeprecationWarning: SQLALCHEMY_TRACK_MODIFICATIONS adds significant overhead and will be disabled by default in the future.  Set it to True or False to suppress this warning.
  warnings.warn(FSADeprecationWarning(
Using cache found in /root/.cache/torch/hub/snakers4_silero-vad_master
/opt/anaconda3/envs/si-dev/lib/python3.8/site-packages/numpy/core/getlimits.py:499: UserWarning: The value of the smallest subnormal for <class 'numpy.float64'> type is zero.
  setattr(self, word, getattr(machar, word).flat[0])
/opt/anaconda3/envs/si-dev/lib/python3.8/site-packages/numpy/core/getlimits.py:89: UserWarning: The value of the smallest subnormal for <class 'numpy.float64'> type is zero.
  return self._float_to_str(self.smallest_subnormal)
/opt/anaconda3/envs/si-dev/lib/python3.8/site-packages/numpy/core/getlimits.py:499: UserWarning: The value of the smallest subnormal for <class 'numpy.float32'> type is zero.
  setattr(self, word, getattr(machar, word).flat[0])
/opt/anaconda3/envs/si-dev/lib/python3.8/site-packages/numpy/core/getlimits.py:89: UserWarning: The value of the smallest subnormal for <class 'numpy.float32'> type is zero.
  return self._float_to_str(self.smallest_subnormal)
/opt/anaconda3/envs/si-dev/lib/python3.8/site-packages/huggingface_hub/utils/_deprecation.py:39: FutureWarning: Pass library_name=False as keyword args. From version 0.8 passing these as positional arguments will result in an error
  warnings.warn(
/opt/anaconda3/envs/si-dev/lib/python3.8/site-packages/flask_sqlalchemy/__init__.py:872: FSADeprecationWarning: SQLALCHEMY_TRACK_MODIFICATIONS adds significant overhead and will be disabled by default in the future.  Set it to True or False to suppress this warning.
  warnings.warn(FSADeprecationWarning(
/opt/anaconda3/envs/si-dev/lib/python3.8/site-packages/flask_sqlalchemy/__init__.py:872: FSADeprecationWarning: SQLALCHEMY_TRACK_MODIFICATIONS adds significant overhead and will be disabled by default in the future.  Set it to True or False to suppress this warning.
  warnings.warn(FSADeprecationWarning(
/home/zhaosheng/VAF-System/demo_flask/utils/preprocess.py:94: UserWarning: To copy construct from a tensor, it is recommended to use sourceTensor.clone().detach() or sourceTensor.clone().detach().requires_grad_(True), rather than torch.tensor(sourceTensor).
  tiny_wav = torch.tensor(
下载完成
torch.Size([960000])
Score:0.5787882804870605
INSERT INTO log (phone, action_type,time,err_type, message,file_url) VALUES ('15151832012', '2', curtime(),'1', 'Bad quality score:0.5787882804870605.','local:/home/zhaosheng/VAF-System/demo_flask/wavs/raw/13654182662/raw_1.wav');
Using cache found in /root/.cache/torch/hub/snakers4_silero-vad_master
/opt/anaconda3/envs/si-dev/lib/python3.8/site-packages/numpy/core/getlimits.py:499: UserWarning: The value of the smallest subnormal for <class 'numpy.float64'> type is zero.
  setattr(self, word, getattr(machar, word).flat[0])
/opt/anaconda3/envs/si-dev/lib/python3.8/site-packages/numpy/core/getlimits.py:89: UserWarning: The value of the smallest subnormal for <class 'numpy.float64'> type is zero.
  return self._float_to_str(self.smallest_subnormal)
/opt/anaconda3/envs/si-dev/lib/python3.8/site-packages/numpy/core/getlimits.py:499: UserWarning: The value of the smallest subnormal for <class 'numpy.float32'> type is zero.
  setattr(self, word, getattr(machar, word).flat[0])
/opt/anaconda3/envs/si-dev/lib/python3.8/site-packages/numpy/core/getlimits.py:89: UserWarning: The value of the smallest subnormal for <class 'numpy.float32'> type is zero.
  return self._float_to_str(self.smallest_subnormal)
/opt/anaconda3/envs/si-dev/lib/python3.8/site-packages/huggingface_hub/utils/_deprecation.py:39: FutureWarning: Pass library_name=False as keyword args. From version 0.8 passing these as positional arguments will result in an error
  warnings.warn(
/opt/anaconda3/envs/si-dev/lib/python3.8/site-packages/flask_sqlalchemy/__init__.py:872: FSADeprecationWarning: SQLALCHEMY_TRACK_MODIFICATIONS adds significant overhead and will be disabled by default in the future.  Set it to True or False to suppress this warning.
  warnings.warn(FSADeprecationWarning(
/opt/anaconda3/envs/si-dev/lib/python3.8/site-packages/flask_sqlalchemy/__init__.py:872: FSADeprecationWarning: SQLALCHEMY_TRACK_MODIFICATIONS adds significant overhead and will be disabled by default in the future.  Set it to True or False to suppress this warning.
  warnings.warn(FSADeprecationWarning(
Using cache found in /root/.cache/torch/hub/snakers4_silero-vad_master
/opt/anaconda3/envs/si-dev/lib/python3.8/site-packages/numpy/core/getlimits.py:499: UserWarning: The value of the smallest subnormal for <class 'numpy.float64'> type is zero.
  setattr(self, word, getattr(machar, word).flat[0])
/opt/anaconda3/envs/si-dev/lib/python3.8/site-packages/numpy/core/getlimits.py:89: UserWarning: The value of the smallest subnormal for <class 'numpy.float64'> type is zero.
  return self._float_to_str(self.smallest_subnormal)
/opt/anaconda3/envs/si-dev/lib/python3.8/site-packages/numpy/core/getlimits.py:499: UserWarning: The value of the smallest subnormal for <class 'numpy.float32'> type is zero.
  setattr(self, word, getattr(machar, word).flat[0])
/opt/anaconda3/envs/si-dev/lib/python3.8/site-packages/numpy/core/getlimits.py:89: UserWarning: The value of the smallest subnormal for <class 'numpy.float32'> type is zero.
  return self._float_to_str(self.smallest_subnormal)
/opt/anaconda3/envs/si-dev/lib/python3.8/site-packages/huggingface_hub/utils/_deprecation.py:39: FutureWarning: Pass library_name=False as keyword args. From version 0.8 passing these as positional arguments will result in an error
  warnings.warn(
/opt/anaconda3/envs/si-dev/lib/python3.8/site-packages/flask_sqlalchemy/__init__.py:872: FSADeprecationWarning: SQLALCHEMY_TRACK_MODIFICATIONS adds significant overhead and will be disabled by default in the future.  Set it to True or False to suppress this warning.
  warnings.warn(FSADeprecationWarning(
/opt/anaconda3/envs/si-dev/lib/python3.8/site-packages/flask_sqlalchemy/__init__.py:872: FSADeprecationWarning: SQLALCHEMY_TRACK_MODIFICATIONS adds significant overhead and will be disabled by default in the future.  Set it to True or False to suppress this warning.
  warnings.warn(FSADeprecationWarning(
Using cache found in /root/.cache/torch/hub/snakers4_silero-vad_master
/opt/anaconda3/envs/si-dev/lib/python3.8/site-packages/numpy/core/getlimits.py:499: UserWarning: The value of the smallest subnormal for <class 'numpy.float64'> type is zero.
  setattr(self, word, getattr(machar, word).flat[0])
/opt/anaconda3/envs/si-dev/lib/python3.8/site-packages/numpy/core/getlimits.py:89: UserWarning: The value of the smallest subnormal for <class 'numpy.float64'> type is zero.
  return self._float_to_str(self.smallest_subnormal)
/opt/anaconda3/envs/si-dev/lib/python3.8/site-packages/numpy/core/getlimits.py:499: UserWarning: The value of the smallest subnormal for <class 'numpy.float32'> type is zero.
  setattr(self, word, getattr(machar, word).flat[0])
/opt/anaconda3/envs/si-dev/lib/python3.8/site-packages/numpy/core/getlimits.py:89: UserWarning: The value of the smallest subnormal for <class 'numpy.float32'> type is zero.
  return self._float_to_str(self.smallest_subnormal)
/opt/anaconda3/envs/si-dev/lib/python3.8/site-packages/huggingface_hub/utils/_deprecation.py:39: FutureWarning: Pass library_name=False as keyword args. From version 0.8 passing these as positional arguments will result in an error
  warnings.warn(
/opt/anaconda3/envs/si-dev/lib/python3.8/site-packages/flask_sqlalchemy/__init__.py:872: FSADeprecationWarning: SQLALCHEMY_TRACK_MODIFICATIONS adds significant overhead and will be disabled by default in the future.  Set it to True or False to suppress this warning.
  warnings.warn(FSADeprecationWarning(
/opt/anaconda3/envs/si-dev/lib/python3.8/site-packages/flask_sqlalchemy/__init__.py:872: FSADeprecationWarning: SQLALCHEMY_TRACK_MODIFICATIONS adds significant overhead and will be disabled by default in the future.  Set it to True or False to suppress this warning.
  warnings.warn(FSADeprecationWarning(
/home/zhaosheng/VAF-System/demo_flask/utils/preprocess.py:94: UserWarning: To copy construct from a tensor, it is recommended to use sourceTensor.clone().detach() or sourceTensor.clone().detach().requires_grad_(True), rather than torch.tensor(sourceTensor).
  tiny_wav = torch.tensor(
下载完成
torch.Size([960000])
Score:0.5787882804870605
INSERT INTO log (phone, action_type,time,err_type, message,file_url) VALUES ('15151832012', '2', curtime(),'1', 'Bad quality score:0.5787882804870605.','local:/home/zhaosheng/VAF-System/demo_flask/wavs/raw/13654182662/raw_1.wav');
Traceback (most recent call last):
  File "/usr/local/lib/python3.8/dist-packages/gunicorn/arbiter.py", line 209, in run
    self.sleep()
  File "/usr/local/lib/python3.8/dist-packages/gunicorn/arbiter.py", line 357, in sleep
    ready = select.select([self.PIPE[0]], [], [], 1.0)
  File "/usr/local/lib/python3.8/dist-packages/gunicorn/arbiter.py", line 242, in handle_chld
    self.reap_workers()
  File "/usr/local/lib/python3.8/dist-packages/gunicorn/arbiter.py", line 525, in reap_workers
    raise HaltServer(reason, self.WORKER_BOOT_ERROR)
gunicorn.errors.HaltServer: <HaltServer 'Worker failed to boot.' 3>

During handling of the above exception, another exception occurred:

Traceback (most recent call last):
  File "/usr/local/bin/gunicorn", line 8, in <module>
    sys.exit(run())
  File "/usr/local/lib/python3.8/dist-packages/gunicorn/app/wsgiapp.py", line 67, in run
    WSGIApplication("%(prog)s [OPTIONS] [APP_MODULE]").run()
  File "/usr/local/lib/python3.8/dist-packages/gunicorn/app/base.py", line 231, in run
    super().run()
  File "/usr/local/lib/python3.8/dist-packages/gunicorn/app/base.py", line 72, in run
    Arbiter(self).run()
  File "/usr/local/lib/python3.8/dist-packages/gunicorn/arbiter.py", line 229, in run
    self.halt(reason=inst.reason, exit_status=inst.exit_status)
  File "/usr/local/lib/python3.8/dist-packages/gunicorn/arbiter.py", line 342, in halt
    self.stop()
  File "/usr/local/lib/python3.8/dist-packages/gunicorn/arbiter.py", line 393, in stop
    time.sleep(0.1)
  File "/usr/local/lib/python3.8/dist-packages/gunicorn/arbiter.py", line 242, in handle_chld
    self.reap_workers()
  File "/usr/local/lib/python3.8/dist-packages/gunicorn/arbiter.py", line 525, in reap_workers
    raise HaltServer(reason, self.WORKER_BOOT_ERROR)
gunicorn.errors.HaltServer: <HaltServer 'Worker failed to boot.' 3>
Traceback (most recent call last):
  File "/usr/local/lib/python3.8/dist-packages/gunicorn/arbiter.py", line 209, in run
    self.sleep()
  File "/usr/local/lib/python3.8/dist-packages/gunicorn/arbiter.py", line 357, in sleep
    ready = select.select([self.PIPE[0]], [], [], 1.0)
  File "/usr/local/lib/python3.8/dist-packages/gunicorn/arbiter.py", line 242, in handle_chld
    self.reap_workers()
  File "/usr/local/lib/python3.8/dist-packages/gunicorn/arbiter.py", line 525, in reap_workers
    raise HaltServer(reason, self.WORKER_BOOT_ERROR)
gunicorn.errors.HaltServer: <HaltServer 'Worker failed to boot.' 3>

During handling of the above exception, another exception occurred:

Traceback (most recent call last):
  File "/usr/local/bin/gunicorn", line 8, in <module>
    sys.exit(run())
  File "/usr/local/lib/python3.8/dist-packages/gunicorn/app/wsgiapp.py", line 67, in run
    WSGIApplication("%(prog)s [OPTIONS] [APP_MODULE]").run()
  File "/usr/local/lib/python3.8/dist-packages/gunicorn/app/base.py", line 231, in run
    super().run()
  File "/usr/local/lib/python3.8/dist-packages/gunicorn/app/base.py", line 72, in run
    Arbiter(self).run()
  File "/usr/local/lib/python3.8/dist-packages/gunicorn/arbiter.py", line 229, in run
    self.halt(reason=inst.reason, exit_status=inst.exit_status)
  File "/usr/local/lib/python3.8/dist-packages/gunicorn/arbiter.py", line 342, in halt
    self.stop()
  File "/usr/local/lib/python3.8/dist-packages/gunicorn/arbiter.py", line 393, in stop
    time.sleep(0.1)
  File "/usr/local/lib/python3.8/dist-packages/gunicorn/arbiter.py", line 242, in handle_chld
    self.reap_workers()
  File "/usr/local/lib/python3.8/dist-packages/gunicorn/arbiter.py", line 525, in reap_workers
    raise HaltServer(reason, self.WORKER_BOOT_ERROR)
gunicorn.errors.HaltServer: <HaltServer 'Worker failed to boot.' 3>
Traceback (most recent call last):
  File "/usr/local/lib/python3.8/dist-packages/gunicorn/arbiter.py", line 209, in run
    self.sleep()
  File "/usr/local/lib/python3.8/dist-packages/gunicorn/arbiter.py", line 357, in sleep
    ready = select.select([self.PIPE[0]], [], [], 1.0)
  File "/usr/local/lib/python3.8/dist-packages/gunicorn/arbiter.py", line 242, in handle_chld
    self.reap_workers()
  File "/usr/local/lib/python3.8/dist-packages/gunicorn/arbiter.py", line 525, in reap_workers
    raise HaltServer(reason, self.WORKER_BOOT_ERROR)
gunicorn.errors.HaltServer: <HaltServer 'Worker failed to boot.' 3>

During handling of the above exception, another exception occurred:

Traceback (most recent call last):
  File "/usr/local/bin/gunicorn", line 8, in <module>
    sys.exit(run())
  File "/usr/local/lib/python3.8/dist-packages/gunicorn/app/wsgiapp.py", line 67, in run
    WSGIApplication("%(prog)s [OPTIONS] [APP_MODULE]").run()
  File "/usr/local/lib/python3.8/dist-packages/gunicorn/app/base.py", line 231, in run
    super().run()
  File "/usr/local/lib/python3.8/dist-packages/gunicorn/app/base.py", line 72, in run
    Arbiter(self).run()
  File "/usr/local/lib/python3.8/dist-packages/gunicorn/arbiter.py", line 229, in run
    self.halt(reason=inst.reason, exit_status=inst.exit_status)
  File "/usr/local/lib/python3.8/dist-packages/gunicorn/arbiter.py", line 342, in halt
    self.stop()
  File "/usr/local/lib/python3.8/dist-packages/gunicorn/arbiter.py", line 393, in stop
    time.sleep(0.1)
  File "/usr/local/lib/python3.8/dist-packages/gunicorn/arbiter.py", line 242, in handle_chld
    self.reap_workers()
  File "/usr/local/lib/python3.8/dist-packages/gunicorn/arbiter.py", line 525, in reap_workers
    raise HaltServer(reason, self.WORKER_BOOT_ERROR)
gunicorn.errors.HaltServer: <HaltServer 'Worker failed to boot.' 3>
Traceback (most recent call last):
  File "/usr/local/lib/python3.8/dist-packages/gunicorn/arbiter.py", line 209, in run
    self.sleep()
  File "/usr/local/lib/python3.8/dist-packages/gunicorn/arbiter.py", line 357, in sleep
    ready = select.select([self.PIPE[0]], [], [], 1.0)
  File "/usr/local/lib/python3.8/dist-packages/gunicorn/arbiter.py", line 242, in handle_chld
    self.reap_workers()
  File "/usr/local/lib/python3.8/dist-packages/gunicorn/arbiter.py", line 525, in reap_workers
    raise HaltServer(reason, self.WORKER_BOOT_ERROR)
gunicorn.errors.HaltServer: <HaltServer 'Worker failed to boot.' 3>

During handling of the above exception, another exception occurred:

Traceback (most recent call last):
  File "/usr/local/bin/gunicorn", line 8, in <module>
    sys.exit(run())
  File "/usr/local/lib/python3.8/dist-packages/gunicorn/app/wsgiapp.py", line 67, in run
    WSGIApplication("%(prog)s [OPTIONS] [APP_MODULE]").run()
  File "/usr/local/lib/python3.8/dist-packages/gunicorn/app/base.py", line 231, in run
    super().run()
  File "/usr/local/lib/python3.8/dist-packages/gunicorn/app/base.py", line 72, in run
    Arbiter(self).run()
  File "/usr/local/lib/python3.8/dist-packages/gunicorn/arbiter.py", line 229, in run
    self.halt(reason=inst.reason, exit_status=inst.exit_status)
  File "/usr/local/lib/python3.8/dist-packages/gunicorn/arbiter.py", line 342, in halt
    self.stop()
  File "/usr/local/lib/python3.8/dist-packages/gunicorn/arbiter.py", line 393, in stop
    time.sleep(0.1)
  File "/usr/local/lib/python3.8/dist-packages/gunicorn/arbiter.py", line 242, in handle_chld
    self.reap_workers()
  File "/usr/local/lib/python3.8/dist-packages/gunicorn/arbiter.py", line 525, in reap_workers
    raise HaltServer(reason, self.WORKER_BOOT_ERROR)
gunicorn.errors.HaltServer: <HaltServer 'Worker failed to boot.' 3>
